[Sun Oct 20 18:26:20 2013] [info] mod_wsgi (pid=25910): Attach interpreter ''.
[Sun Oct 20 18:26:20 2013] [info] mod_wsgi (pid=25911): Attach interpreter ''.
[Mon Oct 21 12:53:25 2013] [info] mod_wsgi (pid=25910): Create interpreter 'rootiocloud'.
[Mon Oct 21 12:53:25 2013] [info] [client 176.58.125.166] mod_wsgi (pid=25910, process='rootiocloud', application='rootiocloud'): Loading WSGI script '/home/csik/public_python/rootiocloud/deploy/rootiocloud.wsgi'.
[Mon Oct 21 12:53:27 2013] [error] --------------------------------------------------------------------------------
[Mon Oct 21 12:53:27 2013] [error] DEBUG in app [/home/csik/public_python/rootiocloud/rootio/app.py:101]:
[Mon Oct 21 12:53:27 2013] [error] lang from browser: en
[Mon Oct 21 12:53:27 2013] [error] --------------------------------------------------------------------------------
[Tue Oct 22 06:25:00 2013] [info] mod_wsgi (pid=25911): Create interpreter 'rootiocloud'.
[Tue Oct 22 06:25:00 2013] [info] [client 41.210.129.107] mod_wsgi (pid=25911, process='rootiocloud', application='rootiocloud'): Loading WSGI script '/home/csik/public_python/rootiocloud/deploy/rootiocloud.wsgi'.
[Tue Oct 22 06:25:01 2013] [error] --------------------------------------------------------------------------------
[Tue Oct 22 06:25:01 2013] [error] DEBUG in app [/home/csik/public_python/rootiocloud/rootio/app.py:101]:
[Tue Oct 22 06:25:01 2013] [error] lang from browser: None
[Tue Oct 22 06:25:01 2013] [error] --------------------------------------------------------------------------------
[Wed Oct 23 06:04:02 2013] [error] --------------------------------------------------------------------------------
[Wed Oct 23 06:04:02 2013] [error] DEBUG in app [/home/csik/public_python/rootiocloud/rootio/app.py:101]:
[Wed Oct 23 06:04:02 2013] [error] lang from browser: None
[Wed Oct 23 06:04:02 2013] [error] --------------------------------------------------------------------------------
[Wed Oct 23 12:30:11 2013] [error] --------------------------------------------------------------------------------
[Wed Oct 23 12:30:11 2013] [error] DEBUG in app [/home/csik/public_python/rootiocloud/rootio/app.py:101]:
[Wed Oct 23 12:30:11 2013] [error] lang from browser: en
[Wed Oct 23 12:30:11 2013] [error] --------------------------------------------------------------------------------
[Thu Oct 24 07:11:15 2013] [error] --------------------------------------------------------------------------------
[Thu Oct 24 07:11:15 2013] [error] DEBUG in app [/home/csik/public_python/rootiocloud/rootio/app.py:93]:
[Thu Oct 24 07:11:15 2013] [error] lang from session: en
[Thu Oct 24 07:11:15 2013] [error] --------------------------------------------------------------------------------
[Fri Oct 25 11:32:03 2013] [error] [client 196.0.32.206] mod_wsgi (pid=25910): Exception occurred processing WSGI script '/home/csik/public_python/rootiocloud/deploy/rootiocloud.wsgi'.
[Fri Oct 25 11:32:03 2013] [error] [client 196.0.32.206] Traceback (most recent call last):
[Fri Oct 25 11:32:03 2013] [error] [client 196.0.32.206]   File "/home/csik/public_python/rootiocloud/venv/lib/python2.7/site-packages/flask/app.py", line 1836, in __call__
[Fri Oct 25 11:32:03 2013] [error] [client 196.0.32.206]     return self.wsgi_app(environ, start_response)
[Fri Oct 25 11:32:03 2013] [error] [client 196.0.32.206]   File "/home/csik/public_python/rootiocloud/venv/lib/python2.7/site-packages/flask/app.py", line 1820, in wsgi_app
[Fri Oct 25 11:32:03 2013] [error] [client 196.0.32.206]     response = self.make_response(self.handle_exception(e))
[Fri Oct 25 11:32:03 2013] [error] [client 196.0.32.206]   File "/home/csik/public_python/rootiocloud/venv/lib/python2.7/site-packages/flask/app.py", line 1403, in handle_exception
[Fri Oct 25 11:32:03 2013] [error] [client 196.0.32.206]     reraise(exc_type, exc_value, tb)
[Fri Oct 25 11:32:03 2013] [error] [client 196.0.32.206]   File "/home/csik/public_python/rootiocloud/venv/lib/python2.7/site-packages/flask/app.py", line 1817, in wsgi_app
[Fri Oct 25 11:32:03 2013] [error] [client 196.0.32.206]     response = self.full_dispatch_request()
[Fri Oct 25 11:32:03 2013] [error] [client 196.0.32.206]   File "/home/csik/public_python/rootiocloud/venv/lib/python2.7/site-packages/flask/app.py", line 1477, in full_dispatch_request
[Fri Oct 25 11:32:03 2013] [error] [client 196.0.32.206]     rv = self.handle_user_exception(e)
[Fri Oct 25 11:32:03 2013] [error] [client 196.0.32.206]   File "/home/csik/public_python/rootiocloud/venv/lib/python2.7/site-packages/flask/app.py", line 1381, in handle_user_exception
[Fri Oct 25 11:32:03 2013] [error] [client 196.0.32.206]     reraise(exc_type, exc_value, tb)
[Fri Oct 25 11:32:03 2013] [error] [client 196.0.32.206]   File "/home/csik/public_python/rootiocloud/venv/lib/python2.7/site-packages/flask/app.py", line 1475, in full_dispatch_request
[Fri Oct 25 11:32:03 2013] [error] [client 196.0.32.206]     rv = self.dispatch_request()
[Fri Oct 25 11:32:03 2013] [error] [client 196.0.32.206]   File "/home/csik/public_python/rootiocloud/venv/lib/python2.7/site-packages/flask/app.py", line 1461, in dispatch_request
[Fri Oct 25 11:32:03 2013] [error] [client 196.0.32.206]     return self.view_functions[rule.endpoint](**req.view_args)
[Fri Oct 25 11:32:03 2013] [error] [client 196.0.32.206]   File "/home/csik/public_python/rootiocloud/rootio/frontend/views.py", line 70, in index
[Fri Oct 25 11:32:03 2013] [error] [client 196.0.32.206]     pagination = User.query.paginate(page=page, per_page=10)
[Fri Oct 25 11:32:03 2013] [error] [client 196.0.32.206]   File "/home/csik/public_python/rootiocloud/venv/lib/python2.7/site-packages/flask_sqlalchemy/__init__.py", line 405, in paginate
[Fri Oct 25 11:32:03 2013] [error] [client 196.0.32.206]     items = self.limit(per_page).offset((page - 1) * per_page).all()
[Fri Oct 25 11:32:03 2013] [error] [client 196.0.32.206]   File "/home/csik/public_python/rootiocloud/venv/lib/python2.7/site-packages/sqlalchemy/orm/query.py", line 2237, in all
[Fri Oct 25 11:32:03 2013] [error] [client 196.0.32.206]     return list(self)
[Fri Oct 25 11:32:03 2013] [error] [client 196.0.32.206]   File "/home/csik/public_python/rootiocloud/venv/lib/python2.7/site-packages/sqlalchemy/orm/query.py", line 2349, in __iter__
[Fri Oct 25 11:32:03 2013] [error] [client 196.0.32.206]     return self._execute_and_instances(context)
[Fri Oct 25 11:32:03 2013] [error] [client 196.0.32.206]   File "/home/csik/public_python/rootiocloud/venv/lib/python2.7/site-packages/sqlalchemy/orm/query.py", line 2364, in _execute_and_instances
[Fri Oct 25 11:32:03 2013] [error] [client 196.0.32.206]     result = conn.execute(querycontext.statement, self._params)
[Fri Oct 25 11:32:03 2013] [error] [client 196.0.32.206]   File "/home/csik/public_python/rootiocloud/venv/lib/python2.7/site-packages/sqlalchemy/engine/base.py", line 662, in execute
[Fri Oct 25 11:32:03 2013] [error] [client 196.0.32.206]     params)
[Fri Oct 25 11:32:03 2013] [error] [client 196.0.32.206]   File "/home/csik/public_python/rootiocloud/venv/lib/python2.7/site-packages/sqlalchemy/engine/base.py", line 761, in _execute_clauseelement
[Fri Oct 25 11:32:03 2013] [error] [client 196.0.32.206]     compiled_sql, distilled_params
[Fri Oct 25 11:32:03 2013] [error] [client 196.0.32.206]   File "/home/csik/public_python/rootiocloud/venv/lib/python2.7/site-packages/sqlalchemy/engine/base.py", line 874, in _execute_context
[Fri Oct 25 11:32:03 2013] [error] [client 196.0.32.206]     context)
[Fri Oct 25 11:32:03 2013] [error] [client 196.0.32.206]   File "/home/csik/public_python/rootiocloud/venv/lib/python2.7/site-packages/sqlalchemy/engine/base.py", line 1024, in _handle_dbapi_exception
[Fri Oct 25 11:32:03 2013] [error] [client 196.0.32.206]     exc_info
[Fri Oct 25 11:32:03 2013] [error] [client 196.0.32.206]   File "/home/csik/public_python/rootiocloud/venv/lib/python2.7/site-packages/sqlalchemy/util/compat.py", line 195, in raise_from_cause
[Fri Oct 25 11:32:03 2013] [error] [client 196.0.32.206]     reraise(type(exception), exception, tb=exc_tb)
[Fri Oct 25 11:32:03 2013] [error] [client 196.0.32.206]   File "/home/csik/public_python/rootiocloud/venv/lib/python2.7/site-packages/sqlalchemy/engine/base.py", line 867, in _execute_context
[Fri Oct 25 11:32:03 2013] [error] [client 196.0.32.206]     context)
[Fri Oct 25 11:32:03 2013] [error] [client 196.0.32.206]   File "/home/csik/public_python/rootiocloud/venv/lib/python2.7/site-packages/sqlalchemy/engine/default.py", line 324, in do_execute
[Fri Oct 25 11:32:03 2013] [error] [client 196.0.32.206]     cursor.execute(statement, parameters)
[Fri Oct 25 11:32:03 2013] [error] [client 196.0.32.206] OperationalError: (OperationalError) SSL connection has been closed unexpectedly
[Fri Oct 25 11:32:03 2013] [error] [client 196.0.32.206]  'SELECT user_user.password AS user_user_password, user_user.id AS user_user_id, user_user.name AS user_user_name, user_user.email AS user_user_email, user_user.openid AS user_user_openid, user_user.activation_key AS user_user_activation_key, user_user.created_time AS user_user_created_time, user_user.last_accessed AS user_user_last_accessed, user_user.avatar AS user_user_avatar, user_user.role_code AS user_user_role_code, user_user.status_code AS user_user_status_code, user_user.user_detail_id AS user_user_user_detail_id \\nFROM user_user \\n LIMIT %(param_1)s OFFSET %(param_2)s' {'param_1': 10, 'param_2': 0}
[Fri Oct 25 11:32:03 2013] [error] --------------------------------------------------------------------------------
[Fri Oct 25 11:32:03 2013] [error] DEBUG in app [/home/csik/public_python/rootiocloud/rootio/app.py:101]:
[Fri Oct 25 11:32:03 2013] [error] lang from browser: en
[Fri Oct 25 11:32:03 2013] [error] --------------------------------------------------------------------------------
[Fri Oct 25 11:32:42 2013] [error] --------------------------------------------------------------------------------
[Fri Oct 25 11:32:42 2013] [error] DEBUG in app [/home/csik/public_python/rootiocloud/rootio/app.py:93]:
[Fri Oct 25 11:32:42 2013] [error] lang from session: en
[Fri Oct 25 11:32:42 2013] [error] --------------------------------------------------------------------------------
[Fri Oct 25 11:32:45 2013] [error] --------------------------------------------------------------------------------
[Fri Oct 25 11:32:45 2013] [error] DEBUG in app [/home/csik/public_python/rootiocloud/rootio/app.py:93]:
[Fri Oct 25 11:32:45 2013] [error] lang from session: en
[Fri Oct 25 11:32:45 2013] [error] --------------------------------------------------------------------------------
[Fri Oct 25 11:32:49 2013] [error] --------------------------------------------------------------------------------
[Fri Oct 25 11:32:49 2013] [error] DEBUG in app [/home/csik/public_python/rootiocloud/rootio/app.py:93]:
[Fri Oct 25 11:32:49 2013] [error] lang from session: en
[Fri Oct 25 11:32:49 2013] [error] --------------------------------------------------------------------------------
[Fri Oct 25 11:32:52 2013] [error] [client 196.0.32.206] mod_wsgi (pid=25910): Exception occurred processing WSGI script '/home/csik/public_python/rootiocloud/deploy/rootiocloud.wsgi'.
[Fri Oct 25 11:32:52 2013] [error] [client 196.0.32.206] Traceback (most recent call last):
[Fri Oct 25 11:32:52 2013] [error] [client 196.0.32.206]   File "/home/csik/public_python/rootiocloud/venv/lib/python2.7/site-packages/flask/app.py", line 1836, in __call__
[Fri Oct 25 11:32:52 2013] [error] [client 196.0.32.206]     return self.wsgi_app(environ, start_response)
[Fri Oct 25 11:32:52 2013] [error] [client 196.0.32.206]   File "/home/csik/public_python/rootiocloud/venv/lib/python2.7/site-packages/flask/app.py", line 1820, in wsgi_app
[Fri Oct 25 11:32:52 2013] [error] [client 196.0.32.206]     response = self.make_response(self.handle_exception(e))
[Fri Oct 25 11:32:52 2013] [error] [client 196.0.32.206]   File "/home/csik/public_python/rootiocloud/venv/lib/python2.7/site-packages/flask/app.py", line 1403, in handle_exception
[Fri Oct 25 11:32:52 2013] [error] [client 196.0.32.206]     reraise(exc_type, exc_value, tb)
[Fri Oct 25 11:32:52 2013] [error] [client 196.0.32.206]   File "/home/csik/public_python/rootiocloud/venv/lib/python2.7/site-packages/flask/app.py", line 1817, in wsgi_app
[Fri Oct 25 11:32:52 2013] [error] [client 196.0.32.206]     response = self.full_dispatch_request()
[Fri Oct 25 11:32:52 2013] [error] [client 196.0.32.206]   File "/home/csik/public_python/rootiocloud/venv/lib/python2.7/site-packages/flask/app.py", line 1477, in full_dispatch_request
[Fri Oct 25 11:32:52 2013] [error] [client 196.0.32.206]     rv = self.handle_user_exception(e)
[Fri Oct 25 11:32:52 2013] [error] [client 196.0.32.206]   File "/home/csik/public_python/rootiocloud/venv/lib/python2.7/site-packages/flask/app.py", line 1381, in handle_user_exception
[Fri Oct 25 11:32:52 2013] [error] [client 196.0.32.206]     reraise(exc_type, exc_value, tb)
[Fri Oct 25 11:32:52 2013] [error] [client 196.0.32.206]   File "/home/csik/public_python/rootiocloud/venv/lib/python2.7/site-packages/flask/app.py", line 1475, in full_dispatch_request
[Fri Oct 25 11:32:52 2013] [error] [client 196.0.32.206]     rv = self.dispatch_request()
[Fri Oct 25 11:32:52 2013] [error] [client 196.0.32.206]   File "/home/csik/public_python/rootiocloud/venv/lib/python2.7/site-packages/flask/app.py", line 1461, in dispatch_request
[Fri Oct 25 11:32:52 2013] [error] [client 196.0.32.206]     return self.view_functions[rule.endpoint](**req.view_args)
[Fri Oct 25 11:32:52 2013] [error] [client 196.0.32.206]   File "/home/csik/public_python/rootiocloud/rootio/frontend/views.py", line 96, in login
[Fri Oct 25 11:32:52 2013] [error] [client 196.0.32.206]     form.password.data)
[Fri Oct 25 11:32:52 2013] [error] [client 196.0.32.206]   File "/home/csik/public_python/rootiocloud/rootio/user/models.py", line 93, in authenticate
[Fri Oct 25 11:32:52 2013] [error] [client 196.0.32.206]     user = cls.query.filter(db.or_(User.name == login, User.email == login)).first()
[Fri Oct 25 11:32:52 2013] [error] [client 196.0.32.206]   File "/home/csik/public_python/rootiocloud/venv/lib/python2.7/site-packages/sqlalchemy/orm/query.py", line 2278, in first
[Fri Oct 25 11:32:52 2013] [error] [client 196.0.32.206]     ret = list(self[0:1])
[Fri Oct 25 11:32:52 2013] [error] [client 196.0.32.206]   File "/home/csik/public_python/rootiocloud/venv/lib/python2.7/site-packages/sqlalchemy/orm/query.py", line 2145, in __getitem__
[Fri Oct 25 11:32:52 2013] [error] [client 196.0.32.206]     return list(res)
[Fri Oct 25 11:32:52 2013] [error] [client 196.0.32.206]   File "/home/csik/public_python/rootiocloud/venv/lib/python2.7/site-packages/sqlalchemy/orm/query.py", line 2349, in __iter__
[Fri Oct 25 11:32:52 2013] [error] [client 196.0.32.206]     return self._execute_and_instances(context)
[Fri Oct 25 11:32:52 2013] [error] [client 196.0.32.206]   File "/home/csik/public_python/rootiocloud/venv/lib/python2.7/site-packages/sqlalchemy/orm/query.py", line 2364, in _execute_and_instances
[Fri Oct 25 11:32:52 2013] [error] [client 196.0.32.206]     result = conn.execute(querycontext.statement, self._params)
[Fri Oct 25 11:32:52 2013] [error] [client 196.0.32.206]   File "/home/csik/public_python/rootiocloud/venv/lib/python2.7/site-packages/sqlalchemy/engine/base.py", line 662, in execute
[Fri Oct 25 11:32:52 2013] [error] [client 196.0.32.206]     params)
[Fri Oct 25 11:32:52 2013] [error] [client 196.0.32.206]   File "/home/csik/public_python/rootiocloud/venv/lib/python2.7/site-packages/sqlalchemy/engine/base.py", line 761, in _execute_clauseelement
[Fri Oct 25 11:32:52 2013] [error] [client 196.0.32.206]     compiled_sql, distilled_params
[Fri Oct 25 11:32:52 2013] [error] [client 196.0.32.206]   File "/home/csik/public_python/rootiocloud/venv/lib/python2.7/site-packages/sqlalchemy/engine/base.py", line 874, in _execute_context
[Fri Oct 25 11:32:52 2013] [error] [client 196.0.32.206]     context)
[Fri Oct 25 11:32:52 2013] [error] [client 196.0.32.206]   File "/home/csik/public_python/rootiocloud/venv/lib/python2.7/site-packages/sqlalchemy/engine/base.py", line 1024, in _handle_dbapi_exception
[Fri Oct 25 11:32:52 2013] [error] [client 196.0.32.206]     exc_info
[Fri Oct 25 11:32:52 2013] [error] [client 196.0.32.206]   File "/home/csik/public_python/rootiocloud/venv/lib/python2.7/site-packages/sqlalchemy/util/compat.py", line 195, in raise_from_cause
[Fri Oct 25 11:32:52 2013] [error] [client 196.0.32.206]     reraise(type(exception), exception, tb=exc_tb)
[Fri Oct 25 11:32:52 2013] [error] [client 196.0.32.206]   File "/home/csik/public_python/rootiocloud/venv/lib/python2.7/site-packages/sqlalchemy/engine/base.py", line 867, in _execute_context
[Fri Oct 25 11:32:52 2013] [error] [client 196.0.32.206]     context)
[Fri Oct 25 11:32:52 2013] [error] [client 196.0.32.206]   File "/home/csik/public_python/rootiocloud/venv/lib/python2.7/site-packages/sqlalchemy/engine/default.py", line 324, in do_execute
[Fri Oct 25 11:32:52 2013] [error] [client 196.0.32.206]     cursor.execute(statement, parameters)
[Fri Oct 25 11:32:52 2013] [error] [client 196.0.32.206] OperationalError: (OperationalError) SSL connection has been closed unexpectedly
[Fri Oct 25 11:32:52 2013] [error] [client 196.0.32.206]  'SELECT user_user.password AS user_user_password, user_user.id AS user_user_id, user_user.name AS user_user_name, user_user.email AS user_user_email, user_user.openid AS user_user_openid, user_user.activation_key AS user_user_activation_key, user_user.created_time AS user_user_created_time, user_user.last_accessed AS user_user_last_accessed, user_user.avatar AS user_user_avatar, user_user.role_code AS user_user_role_code, user_user.status_code AS user_user_status_code, user_user.user_detail_id AS user_user_user_detail_id \\nFROM user_user \\nWHERE user_user.name = %(name_1)s OR user_user.email = %(email_1)s \\n LIMIT %(param_1)s' {'param_1': 1, 'email_1': u'josh', 'name_1': u'josh'}
[Fri Oct 25 11:32:57 2013] [error] [client 196.0.32.206] mod_wsgi (pid=25911): Exception occurred processing WSGI script '/home/csik/public_python/rootiocloud/deploy/rootiocloud.wsgi'.
[Fri Oct 25 11:32:57 2013] [error] [client 196.0.32.206] Traceback (most recent call last):
[Fri Oct 25 11:32:57 2013] [error] [client 196.0.32.206]   File "/home/csik/public_python/rootiocloud/venv/lib/python2.7/site-packages/flask/app.py", line 1836, in __call__
[Fri Oct 25 11:32:57 2013] [error] [client 196.0.32.206]     return self.wsgi_app(environ, start_response)
[Fri Oct 25 11:32:57 2013] [error] [client 196.0.32.206]   File "/home/csik/public_python/rootiocloud/venv/lib/python2.7/site-packages/flask/app.py", line 1820, in wsgi_app
[Fri Oct 25 11:32:57 2013] [error] [client 196.0.32.206]     response = self.make_response(self.handle_exception(e))
[Fri Oct 25 11:32:57 2013] [error] [client 196.0.32.206]   File "/home/csik/public_python/rootiocloud/venv/lib/python2.7/site-packages/flask/app.py", line 1403, in handle_exception
[Fri Oct 25 11:32:57 2013] [error] [client 196.0.32.206]     reraise(exc_type, exc_value, tb)
[Fri Oct 25 11:32:57 2013] [error] [client 196.0.32.206]   File "/home/csik/public_python/rootiocloud/venv/lib/python2.7/site-packages/flask/app.py", line 1817, in wsgi_app
[Fri Oct 25 11:32:57 2013] [error] [client 196.0.32.206]     response = self.full_dispatch_request()
[Fri Oct 25 11:32:57 2013] [error] [client 196.0.32.206]   File "/home/csik/public_python/rootiocloud/venv/lib/python2.7/site-packages/flask/app.py", line 1477, in full_dispatch_request
[Fri Oct 25 11:32:57 2013] [error] [client 196.0.32.206]     rv = self.handle_user_exception(e)
[Fri Oct 25 11:32:57 2013] [error] [client 196.0.32.206]   File "/home/csik/public_python/rootiocloud/venv/lib/python2.7/site-packages/flask/app.py", line 1381, in handle_user_exception
[Fri Oct 25 11:32:57 2013] [error] [client 196.0.32.206]     reraise(exc_type, exc_value, tb)
[Fri Oct 25 11:32:57 2013] [error] [client 196.0.32.206]   File "/home/csik/public_python/rootiocloud/venv/lib/python2.7/site-packages/flask/app.py", line 1475, in full_dispatch_request
[Fri Oct 25 11:32:57 2013] [error] [client 196.0.32.206]     rv = self.dispatch_request()
[Fri Oct 25 11:32:57 2013] [error] [client 196.0.32.206]   File "/home/csik/public_python/rootiocloud/venv/lib/python2.7/site-packages/flask/app.py", line 1461, in dispatch_request
[Fri Oct 25 11:32:57 2013] [error] [client 196.0.32.206]     return self.view_functions[rule.endpoint](**req.view_args)
[Fri Oct 25 11:32:57 2013] [error] [client 196.0.32.206]   File "/home/csik/public_python/rootiocloud/rootio/frontend/views.py", line 96, in login
[Fri Oct 25 11:32:57 2013] [error] [client 196.0.32.206]     form.password.data)
[Fri Oct 25 11:32:57 2013] [error] [client 196.0.32.206]   File "/home/csik/public_python/rootiocloud/rootio/user/models.py", line 93, in authenticate
[Fri Oct 25 11:32:57 2013] [error] [client 196.0.32.206]     user = cls.query.filter(db.or_(User.name == login, User.email == login)).first()
[Fri Oct 25 11:32:57 2013] [error] [client 196.0.32.206]   File "/home/csik/public_python/rootiocloud/venv/lib/python2.7/site-packages/sqlalchemy/orm/query.py", line 2278, in first
[Fri Oct 25 11:32:57 2013] [error] [client 196.0.32.206]     ret = list(self[0:1])
[Fri Oct 25 11:32:57 2013] [error] [client 196.0.32.206]   File "/home/csik/public_python/rootiocloud/venv/lib/python2.7/site-packages/sqlalchemy/orm/query.py", line 2145, in __getitem__
[Fri Oct 25 11:32:57 2013] [error] [client 196.0.32.206]     return list(res)
[Fri Oct 25 11:32:57 2013] [error] [client 196.0.32.206]   File "/home/csik/public_python/rootiocloud/venv/lib/python2.7/site-packages/sqlalchemy/orm/query.py", line 2349, in __iter__
[Fri Oct 25 11:32:57 2013] [error] [client 196.0.32.206]     return self._execute_and_instances(context)
[Fri Oct 25 11:32:57 2013] [error] [client 196.0.32.206]   File "/home/csik/public_python/rootiocloud/venv/lib/python2.7/site-packages/sqlalchemy/orm/query.py", line 2364, in _execute_and_instances
[Fri Oct 25 11:32:57 2013] [error] [client 196.0.32.206]     result = conn.execute(querycontext.statement, self._params)
[Fri Oct 25 11:32:57 2013] [error] [client 196.0.32.206]   File "/home/csik/public_python/rootiocloud/venv/lib/python2.7/site-packages/sqlalchemy/engine/base.py", line 662, in execute
[Fri Oct 25 11:32:57 2013] [error] [client 196.0.32.206]     params)
[Fri Oct 25 11:32:57 2013] [error] [client 196.0.32.206]   File "/home/csik/public_python/rootiocloud/venv/lib/python2.7/site-packages/sqlalchemy/engine/base.py", line 761, in _execute_clauseelement
[Fri Oct 25 11:32:57 2013] [error] [client 196.0.32.206]     compiled_sql, distilled_params
[Fri Oct 25 11:32:57 2013] [error] [client 196.0.32.206]   File "/home/csik/public_python/rootiocloud/venv/lib/python2.7/site-packages/sqlalchemy/engine/base.py", line 874, in _execute_context
[Fri Oct 25 11:32:57 2013] [error] [client 196.0.32.206]     context)
[Fri Oct 25 11:32:57 2013] [error] [client 196.0.32.206]   File "/home/csik/public_python/rootiocloud/venv/lib/python2.7/site-packages/sqlalchemy/engine/base.py", line 1024, in _handle_dbapi_exception
[Fri Oct 25 11:32:57 2013] [error] [client 196.0.32.206]     exc_info
[Fri Oct 25 11:32:57 2013] [error] [client 196.0.32.206]   File "/home/csik/public_python/rootiocloud/venv/lib/python2.7/site-packages/sqlalchemy/util/compat.py", line 195, in raise_from_cause
[Fri Oct 25 11:32:57 2013] [error] [client 196.0.32.206]     reraise(type(exception), exception, tb=exc_tb)
[Fri Oct 25 11:32:57 2013] [error] [client 196.0.32.206]   File "/home/csik/public_python/rootiocloud/venv/lib/python2.7/site-packages/sqlalchemy/engine/base.py", line 867, in _execute_context
[Fri Oct 25 11:32:57 2013] [error] [client 196.0.32.206]     context)
[Fri Oct 25 11:32:57 2013] [error] [client 196.0.32.206]   File "/home/csik/public_python/rootiocloud/venv/lib/python2.7/site-packages/sqlalchemy/engine/default.py", line 324, in do_execute
[Fri Oct 25 11:32:57 2013] [error] [client 196.0.32.206]     cursor.execute(statement, parameters)
[Fri Oct 25 11:32:57 2013] [error] [client 196.0.32.206] OperationalError: (OperationalError) SSL connection has been closed unexpectedly
[Fri Oct 25 11:32:57 2013] [error] [client 196.0.32.206]  'SELECT user_user.password AS user_user_password, user_user.id AS user_user_id, user_user.name AS user_user_name, user_user.email AS user_user_email, user_user.openid AS user_user_openid, user_user.activation_key AS user_user_activation_key, user_user.created_time AS user_user_created_time, user_user.last_accessed AS user_user_last_accessed, user_user.avatar AS user_user_avatar, user_user.role_code AS user_user_role_code, user_user.status_code AS user_user_status_code, user_user.user_detail_id AS user_user_user_detail_id \\nFROM user_user \\nWHERE user_user.name = %(name_1)s OR user_user.email = %(email_1)s \\n LIMIT %(param_1)s' {'param_1': 1, 'email_1': u'josh', 'name_1': u'josh'}
[Fri Oct 25 11:33:55 2013] [error] --------------------------------------------------------------------------------
[Fri Oct 25 11:33:55 2013] [error] DEBUG in app [/home/csik/public_python/rootiocloud/rootio/app.py:93]:
[Fri Oct 25 11:33:55 2013] [error] lang from session: en
[Fri Oct 25 11:33:55 2013] [error] --------------------------------------------------------------------------------
[Fri Oct 25 11:33:59 2013] [error] [client 196.0.32.206] mod_wsgi (pid=25911): Exception occurred processing WSGI script '/home/csik/public_python/rootiocloud/deploy/rootiocloud.wsgi'.
[Fri Oct 25 11:33:59 2013] [error] [client 196.0.32.206] Traceback (most recent call last):
[Fri Oct 25 11:33:59 2013] [error] [client 196.0.32.206]   File "/home/csik/public_python/rootiocloud/venv/lib/python2.7/site-packages/flask/app.py", line 1836, in __call__
[Fri Oct 25 11:33:59 2013] [error] [client 196.0.32.206]     return self.wsgi_app(environ, start_response)
[Fri Oct 25 11:33:59 2013] [error] [client 196.0.32.206]   File "/home/csik/public_python/rootiocloud/venv/lib/python2.7/site-packages/flask/app.py", line 1820, in wsgi_app
[Fri Oct 25 11:33:59 2013] [error] [client 196.0.32.206]     response = self.make_response(self.handle_exception(e))
[Fri Oct 25 11:33:59 2013] [error] [client 196.0.32.206]   File "/home/csik/public_python/rootiocloud/venv/lib/python2.7/site-packages/flask/app.py", line 1403, in handle_exception
[Fri Oct 25 11:33:59 2013] [error] [client 196.0.32.206]     reraise(exc_type, exc_value, tb)
[Fri Oct 25 11:33:59 2013] [error] [client 196.0.32.206]   File "/home/csik/public_python/rootiocloud/venv/lib/python2.7/site-packages/flask/app.py", line 1817, in wsgi_app
[Fri Oct 25 11:33:59 2013] [error] [client 196.0.32.206]     response = self.full_dispatch_request()
[Fri Oct 25 11:33:59 2013] [error] [client 196.0.32.206]   File "/home/csik/public_python/rootiocloud/venv/lib/python2.7/site-packages/flask/app.py", line 1477, in full_dispatch_request
[Fri Oct 25 11:33:59 2013] [error] [client 196.0.32.206]     rv = self.handle_user_exception(e)
[Fri Oct 25 11:33:59 2013] [error] [client 196.0.32.206]   File "/home/csik/public_python/rootiocloud/venv/lib/python2.7/site-packages/flask/app.py", line 1381, in handle_user_exception
[Fri Oct 25 11:33:59 2013] [error] [client 196.0.32.206]     reraise(exc_type, exc_value, tb)
[Fri Oct 25 11:33:59 2013] [error] [client 196.0.32.206]   File "/home/csik/public_python/rootiocloud/venv/lib/python2.7/site-packages/flask/app.py", line 1475, in full_dispatch_request
[Fri Oct 25 11:33:59 2013] [error] [client 196.0.32.206]     rv = self.dispatch_request()
[Fri Oct 25 11:33:59 2013] [error] [client 196.0.32.206]   File "/home/csik/public_python/rootiocloud/venv/lib/python2.7/site-packages/flask/app.py", line 1461, in dispatch_request
[Fri Oct 25 11:33:59 2013] [error] [client 196.0.32.206]     return self.view_functions[rule.endpoint](**req.view_args)
[Fri Oct 25 11:33:59 2013] [error] [client 196.0.32.206]   File "/home/csik/public_python/rootiocloud/rootio/frontend/views.py", line 96, in login
[Fri Oct 25 11:33:59 2013] [error] [client 196.0.32.206]     form.password.data)
[Fri Oct 25 11:33:59 2013] [error] [client 196.0.32.206]   File "/home/csik/public_python/rootiocloud/rootio/user/models.py", line 93, in authenticate
[Fri Oct 25 11:33:59 2013] [error] [client 196.0.32.206]     user = cls.query.filter(db.or_(User.name == login, User.email == login)).first()
[Fri Oct 25 11:33:59 2013] [error] [client 196.0.32.206]   File "/home/csik/public_python/rootiocloud/venv/lib/python2.7/site-packages/sqlalchemy/orm/query.py", line 2278, in first
[Fri Oct 25 11:33:59 2013] [error] [client 196.0.32.206]     ret = list(self[0:1])
[Fri Oct 25 11:33:59 2013] [error] [client 196.0.32.206]   File "/home/csik/public_python/rootiocloud/venv/lib/python2.7/site-packages/sqlalchemy/orm/query.py", line 2145, in __getitem__
[Fri Oct 25 11:33:59 2013] [error] [client 196.0.32.206]     return list(res)
[Fri Oct 25 11:33:59 2013] [error] [client 196.0.32.206]   File "/home/csik/public_python/rootiocloud/venv/lib/python2.7/site-packages/sqlalchemy/orm/query.py", line 2349, in __iter__
[Fri Oct 25 11:33:59 2013] [error] [client 196.0.32.206]     return self._execute_and_instances(context)
[Fri Oct 25 11:33:59 2013] [error] [client 196.0.32.206]   File "/home/csik/public_python/rootiocloud/venv/lib/python2.7/site-packages/sqlalchemy/orm/query.py", line 2364, in _execute_and_instances
[Fri Oct 25 11:33:59 2013] [error] [client 196.0.32.206]     result = conn.execute(querycontext.statement, self._params)
[Fri Oct 25 11:33:59 2013] [error] [client 196.0.32.206]   File "/home/csik/public_python/rootiocloud/venv/lib/python2.7/site-packages/sqlalchemy/engine/base.py", line 662, in execute
[Fri Oct 25 11:33:59 2013] [error] [client 196.0.32.206]     params)
[Fri Oct 25 11:33:59 2013] [error] [client 196.0.32.206]   File "/home/csik/public_python/rootiocloud/venv/lib/python2.7/site-packages/sqlalchemy/engine/base.py", line 761, in _execute_clauseelement
[Fri Oct 25 11:33:59 2013] [error] [client 196.0.32.206]     compiled_sql, distilled_params
[Fri Oct 25 11:33:59 2013] [error] [client 196.0.32.206]   File "/home/csik/public_python/rootiocloud/venv/lib/python2.7/site-packages/sqlalchemy/engine/base.py", line 874, in _execute_context
[Fri Oct 25 11:33:59 2013] [error] [client 196.0.32.206]     context)
[Fri Oct 25 11:33:59 2013] [error] [client 196.0.32.206]   File "/home/csik/public_python/rootiocloud/venv/lib/python2.7/site-packages/sqlalchemy/engine/base.py", line 1024, in _handle_dbapi_exception
[Fri Oct 25 11:33:59 2013] [error] [client 196.0.32.206]     exc_info
[Fri Oct 25 11:33:59 2013] [error] [client 196.0.32.206]   File "/home/csik/public_python/rootiocloud/venv/lib/python2.7/site-packages/sqlalchemy/util/compat.py", line 195, in raise_from_cause
[Fri Oct 25 11:33:59 2013] [error] [client 196.0.32.206]     reraise(type(exception), exception, tb=exc_tb)
[Fri Oct 25 11:33:59 2013] [error] [client 196.0.32.206]   File "/home/csik/public_python/rootiocloud/venv/lib/python2.7/site-packages/sqlalchemy/engine/base.py", line 867, in _execute_context
[Fri Oct 25 11:33:59 2013] [error] [client 196.0.32.206]     context)
[Fri Oct 25 11:33:59 2013] [error] [client 196.0.32.206]   File "/home/csik/public_python/rootiocloud/venv/lib/python2.7/site-packages/sqlalchemy/engine/default.py", line 324, in do_execute
[Fri Oct 25 11:33:59 2013] [error] [client 196.0.32.206]     cursor.execute(statement, parameters)
[Fri Oct 25 11:33:59 2013] [error] [client 196.0.32.206] OperationalError: (OperationalError) SSL connection has been closed unexpectedly
[Fri Oct 25 11:33:59 2013] [error] [client 196.0.32.206]  'SELECT user_user.password AS user_user_password, user_user.id AS user_user_id, user_user.name AS user_user_name, user_user.email AS user_user_email, user_user.openid AS user_user_openid, user_user.activation_key AS user_user_activation_key, user_user.created_time AS user_user_created_time, user_user.last_accessed AS user_user_last_accessed, user_user.avatar AS user_user_avatar, user_user.role_code AS user_user_role_code, user_user.status_code AS user_user_status_code, user_user.user_detail_id AS user_user_user_detail_id \\nFROM user_user \\nWHERE user_user.name = %(name_1)s OR user_user.email = %(email_1)s \\n LIMIT %(param_1)s' {'param_1': 1, 'email_1': u'josh', 'name_1': u'josh'}
[Fri Oct 25 11:36:51 2013] [error] --------------------------------------------------------------------------------
[Fri Oct 25 11:36:51 2013] [error] DEBUG in app [/home/csik/public_python/rootiocloud/rootio/app.py:93]:
[Fri Oct 25 11:36:51 2013] [error] lang from session: en
[Fri Oct 25 11:36:51 2013] [error] --------------------------------------------------------------------------------
[Fri Oct 25 11:36:57 2013] [error] [client 196.0.32.206] mod_wsgi (pid=25910): Exception occurred processing WSGI script '/home/csik/public_python/rootiocloud/deploy/rootiocloud.wsgi'.
[Fri Oct 25 11:36:57 2013] [error] [client 196.0.32.206] Traceback (most recent call last):
[Fri Oct 25 11:36:57 2013] [error] [client 196.0.32.206]   File "/home/csik/public_python/rootiocloud/venv/lib/python2.7/site-packages/flask/app.py", line 1836, in __call__
[Fri Oct 25 11:36:57 2013] [error] [client 196.0.32.206]     return self.wsgi_app(environ, start_response)
[Fri Oct 25 11:36:57 2013] [error] [client 196.0.32.206]   File "/home/csik/public_python/rootiocloud/venv/lib/python2.7/site-packages/flask/app.py", line 1820, in wsgi_app
[Fri Oct 25 11:36:57 2013] [error] [client 196.0.32.206]     response = self.make_response(self.handle_exception(e))
[Fri Oct 25 11:36:57 2013] [error] [client 196.0.32.206]   File "/home/csik/public_python/rootiocloud/venv/lib/python2.7/site-packages/flask/app.py", line 1403, in handle_exception
[Fri Oct 25 11:36:57 2013] [error] [client 196.0.32.206]     reraise(exc_type, exc_value, tb)
[Fri Oct 25 11:36:57 2013] [error] [client 196.0.32.206]   File "/home/csik/public_python/rootiocloud/venv/lib/python2.7/site-packages/flask/app.py", line 1817, in wsgi_app
[Fri Oct 25 11:36:57 2013] [error] [client 196.0.32.206]     response = self.full_dispatch_request()
[Fri Oct 25 11:36:57 2013] [error] [client 196.0.32.206]   File "/home/csik/public_python/rootiocloud/venv/lib/python2.7/site-packages/flask/app.py", line 1477, in full_dispatch_request
[Fri Oct 25 11:36:57 2013] [error] [client 196.0.32.206]     rv = self.handle_user_exception(e)
[Fri Oct 25 11:36:57 2013] [error] [client 196.0.32.206]   File "/home/csik/public_python/rootiocloud/venv/lib/python2.7/site-packages/flask/app.py", line 1381, in handle_user_exception
[Fri Oct 25 11:36:57 2013] [error] [client 196.0.32.206]     reraise(exc_type, exc_value, tb)
[Fri Oct 25 11:36:57 2013] [error] [client 196.0.32.206]   File "/home/csik/public_python/rootiocloud/venv/lib/python2.7/site-packages/flask/app.py", line 1475, in full_dispatch_request
[Fri Oct 25 11:36:57 2013] [error] [client 196.0.32.206]     rv = self.dispatch_request()
[Fri Oct 25 11:36:57 2013] [error] [client 196.0.32.206]   File "/home/csik/public_python/rootiocloud/venv/lib/python2.7/site-packages/flask/app.py", line 1461, in dispatch_request
[Fri Oct 25 11:36:57 2013] [error] [client 196.0.32.206]     return self.view_functions[rule.endpoint](**req.view_args)
[Fri Oct 25 11:36:57 2013] [error] [client 196.0.32.206]   File "/home/csik/public_python/rootiocloud/rootio/frontend/views.py", line 96, in login
[Fri Oct 25 11:36:57 2013] [error] [client 196.0.32.206]     form.password.data)
[Fri Oct 25 11:36:57 2013] [error] [client 196.0.32.206]   File "/home/csik/public_python/rootiocloud/rootio/user/models.py", line 93, in authenticate
[Fri Oct 25 11:36:57 2013] [error] [client 196.0.32.206]     user = cls.query.filter(db.or_(User.name == login, User.email == login)).first()
[Fri Oct 25 11:36:57 2013] [error] [client 196.0.32.206]   File "/home/csik/public_python/rootiocloud/venv/lib/python2.7/site-packages/sqlalchemy/orm/query.py", line 2278, in first
[Fri Oct 25 11:36:57 2013] [error] [client 196.0.32.206]     ret = list(self[0:1])
[Fri Oct 25 11:36:57 2013] [error] [client 196.0.32.206]   File "/home/csik/public_python/rootiocloud/venv/lib/python2.7/site-packages/sqlalchemy/orm/query.py", line 2145, in __getitem__
[Fri Oct 25 11:36:57 2013] [error] [client 196.0.32.206]     return list(res)
[Fri Oct 25 11:36:57 2013] [error] [client 196.0.32.206]   File "/home/csik/public_python/rootiocloud/venv/lib/python2.7/site-packages/sqlalchemy/orm/query.py", line 2349, in __iter__
[Fri Oct 25 11:36:57 2013] [error] [client 196.0.32.206]     return self._execute_and_instances(context)
[Fri Oct 25 11:36:57 2013] [error] [client 196.0.32.206]   File "/home/csik/public_python/rootiocloud/venv/lib/python2.7/site-packages/sqlalchemy/orm/query.py", line 2364, in _execute_and_instances
[Fri Oct 25 11:36:57 2013] [error] [client 196.0.32.206]     result = conn.execute(querycontext.statement, self._params)
[Fri Oct 25 11:36:57 2013] [error] [client 196.0.32.206]   File "/home/csik/public_python/rootiocloud/venv/lib/python2.7/site-packages/sqlalchemy/engine/base.py", line 662, in execute
[Fri Oct 25 11:36:57 2013] [error] [client 196.0.32.206]     params)
[Fri Oct 25 11:36:57 2013] [error] [client 196.0.32.206]   File "/home/csik/public_python/rootiocloud/venv/lib/python2.7/site-packages/sqlalchemy/engine/base.py", line 761, in _execute_clauseelement
[Fri Oct 25 11:36:57 2013] [error] [client 196.0.32.206]     compiled_sql, distilled_params
[Fri Oct 25 11:36:57 2013] [error] [client 196.0.32.206]   File "/home/csik/public_python/rootiocloud/venv/lib/python2.7/site-packages/sqlalchemy/engine/base.py", line 874, in _execute_context
[Fri Oct 25 11:36:57 2013] [error] [client 196.0.32.206]     context)
[Fri Oct 25 11:36:57 2013] [error] [client 196.0.32.206]   File "/home/csik/public_python/rootiocloud/venv/lib/python2.7/site-packages/sqlalchemy/engine/base.py", line 1024, in _handle_dbapi_exception
[Fri Oct 25 11:36:57 2013] [error] [client 196.0.32.206]     exc_info
[Fri Oct 25 11:36:57 2013] [error] [client 196.0.32.206]   File "/home/csik/public_python/rootiocloud/venv/lib/python2.7/site-packages/sqlalchemy/util/compat.py", line 195, in raise_from_cause
[Fri Oct 25 11:36:57 2013] [error] [client 196.0.32.206]     reraise(type(exception), exception, tb=exc_tb)
[Fri Oct 25 11:36:57 2013] [error] [client 196.0.32.206]   File "/home/csik/public_python/rootiocloud/venv/lib/python2.7/site-packages/sqlalchemy/engine/base.py", line 867, in _execute_context
[Fri Oct 25 11:36:57 2013] [error] [client 196.0.32.206]     context)
[Fri Oct 25 11:36:57 2013] [error] [client 196.0.32.206]   File "/home/csik/public_python/rootiocloud/venv/lib/python2.7/site-packages/sqlalchemy/engine/default.py", line 324, in do_execute
[Fri Oct 25 11:36:57 2013] [error] [client 196.0.32.206]     cursor.execute(statement, parameters)
[Fri Oct 25 11:36:57 2013] [error] [client 196.0.32.206] OperationalError: (OperationalError) SSL connection has been closed unexpectedly
[Fri Oct 25 11:36:57 2013] [error] [client 196.0.32.206]  'SELECT user_user.password AS user_user_password, user_user.id AS user_user_id, user_user.name AS user_user_name, user_user.email AS user_user_email, user_user.openid AS user_user_openid, user_user.activation_key AS user_user_activation_key, user_user.created_time AS user_user_created_time, user_user.last_accessed AS user_user_last_accessed, user_user.avatar AS user_user_avatar, user_user.role_code AS user_user_role_code, user_user.status_code AS user_user_status_code, user_user.user_detail_id AS user_user_user_detail_id \\nFROM user_user \\nWHERE user_user.name = %(name_1)s OR user_user.email = %(email_1)s \\n LIMIT %(param_1)s' {'param_1': 1, 'email_1': u'admin', 'name_1': u'admin'}
[Fri Oct 25 11:40:43 2013] [info] mod_wsgi (pid=25911): Shutdown requested 'rootiocloud'.
[Fri Oct 25 11:40:43 2013] [info] mod_wsgi (pid=25910): Shutdown requested 'rootiocloud'.
[Fri Oct 25 11:40:43 2013] [info] mod_wsgi (pid=25911): Stopping process 'rootiocloud'.
[Fri Oct 25 11:40:43 2013] [info] mod_wsgi (pid=25910): Stopping process 'rootiocloud'.
[Fri Oct 25 11:40:43 2013] [info] mod_wsgi (pid=25911): Destroying interpreters.
[Fri Oct 25 11:40:43 2013] [info] mod_wsgi (pid=25910): Destroying interpreters.
[Fri Oct 25 11:40:43 2013] [info] mod_wsgi (pid=25911): Destroy interpreter 'rootiocloud'.
[Fri Oct 25 11:40:43 2013] [info] mod_wsgi (pid=25910): Destroy interpreter 'rootiocloud'.
[Fri Oct 25 11:40:43 2013] [info] mod_wsgi (pid=25911): Cleanup interpreter ''.
[Fri Oct 25 11:40:43 2013] [info] mod_wsgi (pid=25910): Cleanup interpreter ''.
[Fri Oct 25 11:40:43 2013] [info] mod_wsgi (pid=25911): Terminating Python.
[Fri Oct 25 11:40:43 2013] [info] mod_wsgi (pid=25910): Terminating Python.
[Fri Oct 25 11:40:43 2013] [info] mod_wsgi (pid=25911): Python has shutdown.
[Fri Oct 25 11:40:43 2013] [info] mod_wsgi (pid=25910): Python has shutdown.
[Fri Oct 25 11:40:43 2013] [info] mod_wsgi (pid=31811): Attach interpreter ''.
[Fri Oct 25 11:40:43 2013] [info] mod_wsgi (pid=31810): Attach interpreter ''.
[Fri Oct 25 11:40:47 2013] [info] mod_wsgi (pid=31811): Create interpreter 'rootio_web'.
[Fri Oct 25 11:40:47 2013] [info] [client 196.0.32.206] mod_wsgi (pid=31811, process='rootio_web', application='rootio_web'): Loading WSGI script '/home/csik/public_python/rootio_web/deploy/rootiocloud.wsgi'.
[Fri Oct 25 11:40:47 2013] [error] [client 196.0.32.206] mod_wsgi (pid=31811): Target WSGI script '/home/csik/public_python/rootio_web/deploy/rootiocloud.wsgi' cannot be loaded as Python module.
[Fri Oct 25 11:40:47 2013] [error] [client 196.0.32.206] mod_wsgi (pid=31811): Exception occurred processing WSGI script '/home/csik/public_python/rootio_web/deploy/rootiocloud.wsgi'.
[Fri Oct 25 11:40:47 2013] [error] [client 196.0.32.206] Traceback (most recent call last):
[Fri Oct 25 11:40:47 2013] [error] [client 196.0.32.206]   File "/home/csik/public_python/rootio_web/deploy/rootiocloud.wsgi", line 10, in <module>
[Fri Oct 25 11:40:47 2013] [error] [client 196.0.32.206]     execfile(activate_this, dict(__file__=activate_this))
[Fri Oct 25 11:40:47 2013] [error] [client 196.0.32.206] IOError: [Errno 2] No such file or directory: '/home/csik/public_python/rootiocloud/deploy/../venv/bin/activate_this.py'
[Fri Oct 25 11:40:48 2013] [info] mod_wsgi (pid=31810): Create interpreter 'rootio_web'.
[Fri Oct 25 11:40:48 2013] [info] [client 196.0.32.206] mod_wsgi (pid=31810, process='rootio_web', application='rootio_web'): Loading WSGI script '/home/csik/public_python/rootio_web/deploy/rootiocloud.wsgi'.
[Fri Oct 25 11:40:48 2013] [error] [client 196.0.32.206] mod_wsgi (pid=31810): Target WSGI script '/home/csik/public_python/rootio_web/deploy/rootiocloud.wsgi' cannot be loaded as Python module.
[Fri Oct 25 11:40:48 2013] [error] [client 196.0.32.206] mod_wsgi (pid=31810): Exception occurred processing WSGI script '/home/csik/public_python/rootio_web/deploy/rootiocloud.wsgi'.
[Fri Oct 25 11:40:48 2013] [error] [client 196.0.32.206] Traceback (most recent call last):
[Fri Oct 25 11:40:48 2013] [error] [client 196.0.32.206]   File "/home/csik/public_python/rootio_web/deploy/rootiocloud.wsgi", line 10, in <module>
[Fri Oct 25 11:40:48 2013] [error] [client 196.0.32.206]     execfile(activate_this, dict(__file__=activate_this))
[Fri Oct 25 11:40:48 2013] [error] [client 196.0.32.206] IOError: [Errno 2] No such file or directory: '/home/csik/public_python/rootiocloud/deploy/../venv/bin/activate_this.py'
[Fri Oct 25 11:40:49 2013] [info] [client 196.0.32.206] mod_wsgi (pid=31811, process='rootio_web', application='rootio_web'): Loading WSGI script '/home/csik/public_python/rootio_web/deploy/rootiocloud.wsgi'.
[Fri Oct 25 11:40:49 2013] [error] [client 196.0.32.206] mod_wsgi (pid=31811): Target WSGI script '/home/csik/public_python/rootio_web/deploy/rootiocloud.wsgi' cannot be loaded as Python module.
[Fri Oct 25 11:40:49 2013] [error] [client 196.0.32.206] mod_wsgi (pid=31811): Exception occurred processing WSGI script '/home/csik/public_python/rootio_web/deploy/rootiocloud.wsgi'.
[Fri Oct 25 11:40:49 2013] [error] [client 196.0.32.206] Traceback (most recent call last):
[Fri Oct 25 11:40:49 2013] [error] [client 196.0.32.206]   File "/home/csik/public_python/rootio_web/deploy/rootiocloud.wsgi", line 10, in <module>
[Fri Oct 25 11:40:49 2013] [error] [client 196.0.32.206]     execfile(activate_this, dict(__file__=activate_this))
[Fri Oct 25 11:40:49 2013] [error] [client 196.0.32.206] IOError: [Errno 2] No such file or directory: '/home/csik/public_python/rootiocloud/deploy/../venv/bin/activate_this.py'
[Fri Oct 25 11:40:50 2013] [info] [client 196.0.32.206] mod_wsgi (pid=31810, process='rootio_web', application='rootio_web'): Loading WSGI script '/home/csik/public_python/rootio_web/deploy/rootiocloud.wsgi'.
[Fri Oct 25 11:40:50 2013] [error] [client 196.0.32.206] mod_wsgi (pid=31810): Target WSGI script '/home/csik/public_python/rootio_web/deploy/rootiocloud.wsgi' cannot be loaded as Python module.
[Fri Oct 25 11:40:50 2013] [error] [client 196.0.32.206] mod_wsgi (pid=31810): Exception occurred processing WSGI script '/home/csik/public_python/rootio_web/deploy/rootiocloud.wsgi'.
[Fri Oct 25 11:40:50 2013] [error] [client 196.0.32.206] Traceback (most recent call last):
[Fri Oct 25 11:40:50 2013] [error] [client 196.0.32.206]   File "/home/csik/public_python/rootio_web/deploy/rootiocloud.wsgi", line 10, in <module>
[Fri Oct 25 11:40:50 2013] [error] [client 196.0.32.206]     execfile(activate_this, dict(__file__=activate_this))
[Fri Oct 25 11:40:50 2013] [error] [client 196.0.32.206] IOError: [Errno 2] No such file or directory: '/home/csik/public_python/rootiocloud/deploy/../venv/bin/activate_this.py'
[Fri Oct 25 11:42:02 2013] [info] [client 196.0.32.206] mod_wsgi (pid=31811, process='rootio_web', application='rootio_web'): Loading WSGI script '/home/csik/public_python/rootio_web/deploy/rootiocloud.wsgi'.
[Fri Oct 25 11:42:03 2013] [error] --------------------------------------------------------------------------------
[Fri Oct 25 11:42:03 2013] [error] DEBUG in app [/home/csik/public_python/rootio_web/rootio/app.py:93]:
[Fri Oct 25 11:42:03 2013] [error] lang from session: en
[Fri Oct 25 11:42:03 2013] [error] --------------------------------------------------------------------------------
[Fri Oct 25 11:42:03 2013] [info] [client 196.0.32.206] mod_wsgi (pid=31810, process='rootio_web', application='rootio_web'): Loading WSGI script '/home/csik/public_python/rootio_web/deploy/rootiocloud.wsgi'.
[Fri Oct 25 11:42:04 2013] [error] --------------------------------------------------------------------------------
[Fri Oct 25 11:42:04 2013] [error] DEBUG in app [/home/csik/public_python/rootio_web/rootio/app.py:93]:
[Fri Oct 25 11:42:04 2013] [error] lang from session: en
[Fri Oct 25 11:42:04 2013] [error] --------------------------------------------------------------------------------
[Fri Oct 25 11:42:04 2013] [error] --------------------------------------------------------------------------------
[Fri Oct 25 11:42:04 2013] [error] DEBUG in app [/home/csik/public_python/rootio_web/rootio/app.py:93]:
[Fri Oct 25 11:42:04 2013] [error] lang from session: en
[Fri Oct 25 11:42:04 2013] [error] --------------------------------------------------------------------------------
[Fri Oct 25 11:42:58 2013] [info] mod_wsgi (pid=31811): Shutdown requested 'rootio_web'.
[Fri Oct 25 11:42:58 2013] [info] mod_wsgi (pid=31810): Shutdown requested 'rootio_web'.
[Fri Oct 25 11:42:58 2013] [info] mod_wsgi (pid=31811): Stopping process 'rootio_web'.
[Fri Oct 25 11:42:58 2013] [info] mod_wsgi (pid=31810): Stopping process 'rootio_web'.
[Fri Oct 25 11:42:58 2013] [info] mod_wsgi (pid=31811): Destroying interpreters.
[Fri Oct 25 11:42:58 2013] [info] mod_wsgi (pid=31810): Destroying interpreters.
[Fri Oct 25 11:42:58 2013] [info] mod_wsgi (pid=31810): Destroy interpreter 'rootio_web'.
[Fri Oct 25 11:42:58 2013] [info] mod_wsgi (pid=31811): Destroy interpreter 'rootio_web'.
[Fri Oct 25 11:42:58 2013] [info] mod_wsgi (pid=31811): Cleanup interpreter ''.
[Fri Oct 25 11:42:58 2013] [info] mod_wsgi (pid=31810): Cleanup interpreter ''.
[Fri Oct 25 11:42:58 2013] [info] mod_wsgi (pid=31811): Terminating Python.
[Fri Oct 25 11:42:58 2013] [info] mod_wsgi (pid=31810): Terminating Python.
[Fri Oct 25 11:42:58 2013] [info] mod_wsgi (pid=31811): Python has shutdown.
[Fri Oct 25 11:42:58 2013] [info] mod_wsgi (pid=31810): Python has shutdown.
[Fri Oct 25 11:42:58 2013] [info] mod_wsgi (pid=32172): Attach interpreter ''.
[Fri Oct 25 11:42:58 2013] [info] mod_wsgi (pid=32173): Attach interpreter ''.
[Fri Oct 25 11:43:00 2013] [info] mod_wsgi (pid=32172): Create interpreter 'rootio_web'.
[Fri Oct 25 11:43:00 2013] [info] [client 196.0.32.206] mod_wsgi (pid=32172, process='rootio_web', application='rootio_web'): Loading WSGI script '/home/csik/public_python/rootio_web/deploy/rootio_web.wsgi'.
[Fri Oct 25 11:43:01 2013] [error] --------------------------------------------------------------------------------
[Fri Oct 25 11:43:01 2013] [error] DEBUG in app [/home/csik/public_python/rootio_web/rootio/app.py:93]:
[Fri Oct 25 11:43:01 2013] [error] lang from session: en
[Fri Oct 25 11:43:01 2013] [error] --------------------------------------------------------------------------------
[Fri Oct 25 11:43:01 2013] [info] mod_wsgi (pid=32173): Create interpreter 'rootio_web'.
[Fri Oct 25 11:43:01 2013] [info] [client 196.0.32.206] mod_wsgi (pid=32173, process='rootio_web', application='rootio_web'): Loading WSGI script '/home/csik/public_python/rootio_web/deploy/rootio_web.wsgi'.
[Fri Oct 25 11:43:02 2013] [error] --------------------------------------------------------------------------------
[Fri Oct 25 11:43:02 2013] [error] DEBUG in app [/home/csik/public_python/rootio_web/rootio/app.py:93]:
[Fri Oct 25 11:43:02 2013] [error] lang from session: en
[Fri Oct 25 11:43:02 2013] [error] --------------------------------------------------------------------------------
[Fri Oct 25 11:43:02 2013] [error] --------------------------------------------------------------------------------
[Fri Oct 25 11:43:02 2013] [error] DEBUG in app [/home/csik/public_python/rootio_web/rootio/app.py:93]:
[Fri Oct 25 11:43:02 2013] [error] lang from session: en
[Fri Oct 25 11:43:02 2013] [error] --------------------------------------------------------------------------------
